<?xml version="1.0" ?>
<robot name="bazu" xmlns:xacro="http://ros.org/wiki/xacro">

    <link name="world">
    </link>

    <link name="base_link">
        <inertial>
            <origin xyz="0.0 0.0 0.025" rpy="0.0 0.0 0.0"/>
            <mass value="5.0"/>
            <inertia ixx="0.0135" ixy="0.0" ixz="0.0" iyy="0.0135" iyz="0.0" izz="0.025"/>
        </inertial>
        <visual name="">
            <origin xyz="0.0 0.0 0.025" rpy="0.0 0.0 0.0"/>
            <geometry>
                <cylinder radius="0.1" length="0.05"/>
            </geometry>
            <material name="">
                <color rgba="1.0 0.0 0.0 1.0"/>
                <texture filename=""/>
            </material>
        </visual>
        <collision>
            <origin xyz="0.0 0.0 0.025" rpy="0.0 0.0 0.0"/>
            <geometry>
                <cylinder radius="0.1" length="0.05"/>
            </geometry>
        </collision>
    </link>

    <joint name="joint_base" type="fixed">
        <origin xyz="0.0 0.0 0.0" rpy="0.0 0.0 0.0"/>
        <parent link="world"/>
        <child link="base_link"/>
        <axis xyz="0.0 0.0 0.0"/>
        <limit lower="0.0" upper="0.0" effort="0.0" velocity="0.0"/>
    </joint>

    <link name="link_1">
        <inertial>
            <origin xyz="0.0 0.0 0.25" rpy="0.0 0.0 0.0"/>
            <mass value="5.0"/>
            <inertia ixx="0.1073" ixy="0.0" ixz="0.0" iyy="0.1073" iyz="0.0" izz="0.00625"/>
        </inertial>
        <visual name="">
            <origin xyz="0.0 0.0 0.25" rpy="0.0 0.0 0.0"/>
            <geometry>
                <cylinder radius="0.05" length="0.5"/>
            </geometry>
            <material name="">
                <color rgba="1.0 0.0 0.0 1.0"/>
                <texture filename=""/>
            </material>
        </visual>
        <collision>
            <origin xyz="0.0 0.0 0.25" rpy="0.0 0.0 0.0"/>
            <geometry>
                <cylinder radius="0.05" length="0.5"/>
            </geometry>
        </collision>
    </link>

    <joint name="joint_1" type="continuous">
        <origin xyz="0.0 0.0 0.05" rpy="0.0 0.0 0.0"/>
        <parent link="base_link"/>
        <child link="link_1"/>
        <axis xyz="0.0 0.0 1.0"/>
    </joint>

    <link name="link_2">
        <inertial>
            <origin xyz="0.0 0.0 0.2" rpy="0.0 0.0 0.0"/>
            <mass value="2.0"/>
            <inertia ixx="0.0279" ixy="0.0" ixz="0.0" iyy="0.0279" iyz="0.0" izz="0.0025"/>
        </inertial>
        <visual>
            <origin xyz="0.0 0.0 0.2" rpy="0.0 0.0 0.0"/>
            <geometry>
               <cylinder radius="0.05" length="0.4"/>
            </geometry>
            <material name="">
                <color rgba="1.0 0.0 0.0 1.0"/>
                <texture filename=""/>
            </material>
        </visual>
        <collision>
            <origin xyz="0.0 0.0 0.2" rpy="0.0 0.0 0.0"/>
            <geometry>
               <cylinder radius="0.05" length="0.4"/>
            </geometry>
        </collision>
    </link>

    <joint name="joint_2" type="continuous">
        <axis xyz="0 1 0"/>
        <parent link="link_1"/>
        <child link="link_2"/>
        <origin rpy="0 1.5708 0" xyz="0.0 -0.1 0.45"/>
    </joint>

    <link name="link_3">
        <inertial>
            <origin xyz="0.0 0.0 0.2" rpy="0.0 0.0 0.0"/>
            <mass value="2.0"/>
            <inertia ixx="0.0279" ixy="0.0" ixz="0.0" iyy="0.0279" iyz="0.0" izz="0.0025"/>
        </inertial>
        <visual>
            <origin xyz="0.0 0.0 0.2" rpy="0.0 0.0 0.0"/>
            <geometry>
               <cylinder radius="0.05" length="0.4"/>
            </geometry>
            <material name="">
                <color rgba="1.0 0.0 0.0 1.0"/>
                <texture filename=""/>
            </material>
        </visual>
        <collision>
            <origin xyz="0.0 0.0 0.2" rpy="0.0 0.0 0.0"/>
            <geometry>
               <cylinder radius="0.05" length="0.4"/>
            </geometry>
        </collision>
    </link>

    <joint name="joint_3" type="continuous">
        <axis xyz="0 1 0"/>
        <parent link="link_2"/>
        <child link="link_3"/>
        <origin rpy="0 0 0" xyz="0.0 0.1 0.35"/>
    </joint>

    <link name="link_4">
        <inertial>
            <origin xyz="0.0 0.0 0.025" rpy="0.0 0.0 0.0"/>
            <mass value="1.0"/>
            <inertia ixx="0.00417" ixy="0.0" ixz="0.0" iyy="0.00417" iyz="0.0" izz="0.00417"/>
        </inertial>
        <visual>
            <origin xyz="0.0 0.0 0.025" rpy="0.0 0.0 0.0"/>
            <geometry>
               <box size="0.05 0.05 0.05"/>
            </geometry>
            <material name="">
                <color rgba="1.0 0.0 0.0 1.0"/>
                <texture filename=""/>
            </material>
        </visual>
        <collision>
            <origin xyz="0.0 0.0 0.025" rpy="0.0 0.0 0.0"/>
            <geometry>
               <box size="0.05 0.05 0.05"/>
            </geometry>
        </collision>
    </link>

    <joint name="joint_4" type="continuous">
        <axis xyz="0 0 1"/>
        <parent link="link_3"/>
        <child link="link_4"/>
        <origin rpy="0 0 0" xyz="0.0 0 0.4"/>
    </joint>



    <transmission name ="trans_1">
    <type>transmission_interface/SimpleTransmission</type>
    <joint name="joint_1">
        <hardwareInterface>hardware_interface/PositionJointInterface</hardwareInterface>
    </joint>
    <actuator name="motor_1">
        <hardwareInterface>hardware_interface/PositionJointInterface</hardwareInterface>
        <mechanicalReduction>1</mechanicalReduction>
    </actuator>
    </transmission>

    <transmission name ="trans_2">
    <type>transmission_interface/SimpleTransmission</type>
    <joint name="joint_2">
        <hardwareInterface>hardware_interface/PositionJointInterface</hardwareInterface>
    </joint>
    <actuator name="motor_2">
        <hardwareInterface>hardware_interface/PositionJointInterface</hardwareInterface>
        <mechanicalReduction>1</mechanicalReduction>
    </actuator>
</transmission>

<transmission name ="trans_3">
    <type>transmission_interface/SimpleTransmission</type>
    <joint name="joint_3">
        <hardwareInterface>hardware_interface/PositionJointInterface</hardwareInterface>
    </joint>
    <actuator name="motor_3">
        <hardwareInterface>hardware_interface/PositionJointInterface</hardwareInterface>
        <mechanicalReduction>1</mechanicalReduction>
    </actuator>
</transmission>

<transmission name ="trans_4">
    <type>transmission_interface/SimpleTransmission</type>
    <joint name="joint_4">
        <hardwareInterface>hardware_interface/PositionJointInterface</hardwareInterface>
    </joint>
    <actuator name="motor_4">
        <hardwareInterface>hardware_interface/PositionJointInterface</hardwareInterface>
        <mechanicalReduction>1</mechanicalReduction>
    </actuator>
</transmission>

<gazebo>
    <plugin name="control" filename="libgazebo_ros_control.so">
    <robotSimType> gazebo_ros_control/DefaultRobotHWSim </robotSimType>
    <legacyModeNS>true</legacyModeNS>
    </plugin>
    
</gazebo>

<gazebo reference="base_link">
    <material>Gazebo/Black</material>
</gazebo>
<gazebo reference="link_1">
    <material>Gazebo/Grey</material>
</gazebo>
<gazebo reference="link_2">
    <material>Gazebo/Orange</material>
</gazebo>
<gazebo reference="link_3">
    <material>Gazebo/Black</material>
</gazebo>
<gazebo reference="link_4">
    <material>Gazebo/Yellow</material>
</gazebo>

</robot>